Workbook

Sheet Task List
B2: Task List | C2: Assigned to | D2: Status Update | E2: Comments
B3: Budget | C3: Sanjana , Snehal | D3: Budget appoved | E3: PR done for budget line items
B4: Registration form for Researchers (LPI and MPI) | C4: Aakash , Ruchi | D4: Follow-ups ongoing with Hub spocs | E4: 103 PIs registered
B5: Marketing and Branding | C5: Marketing team | D5: Base creatives ready, to be reviewed
B6: Event flow and Agenda | C6: Sanjana / Hardik / Kiran sir | D6: Tentative agenda ready
B7: Registration Kit | C7: HR & Swapneel/ Aditya | D7: Order placed for 200 as of now
B8: Memento | C8: Aakash, Sanjana, Swapneel | D8: Order placed for 12 Qubit crystals
B9: Poster Presentation | C9: Ruchi & Marketing | D9: Follow-ups ongoing with Hub spocs
B10: Tech Expo | C10: Elton & Marketing team | D10: Follow-ups ongoing with Hub spocs
B11: Logistics (RP, Rooms, local transport, inside IITB transport) | C11: Puja/ Deepawali
B12: WiFi and Technical Support | C12: Wajid
B13: VIPs coordination and comms | C13: Puja
B14: Hub/TG Presentations | C14: Srishti, Puja | D14: Template sent to CEOs, deadline April 05
B15: Venue readiness and Event Management monitoring | C15: Santosh, Swapneel and Aditya
B16: Registration Desk | C16: Key Event
B17: Stall Set-up | C17: Elton & Aakash | D17: 20 booth locations identified
B18: Photography and Videography | C18: Key Event
B19: Media and PR | C19: Aakash/Key Events
B20: GH Accommodation - Room allotment | C20: Deepawali/ Puja | D20: 67 Rooms Booked, Awaiting list of attendees from DST/MGB/MTRC
B21: Hostel Accommodation | C21: Deepawali/ Puja | D21: 35 room booking done | E21: Student list to be finalized once poster registrations are received
B22: Gate Pass | C22: Deepawali/Puja/Ruchi
B23: Technical Bulletin | C23: Joyita/Prasobh + Marketing team | D23: Content received from IITB, IISc. Bulletin structure to be decided
B24: Poster Presentation Template | C24: Marketing team | D24: Rutuja to work on A0 size poster template
B25: Students to submit Posters as per template | C25: Ruchi | D25: Emailers to be sent by 25-26, deadline - April 4
B26: Poster Presentation Awards | C26: Marketing + Admin
B27: VIP Escort Volunteers | D27: To be decided
B30: Event Day
B31: Logistics - cab support (9-12) | C31: Deepawali, Srishti
B32: GH and hostel accommodation support (9-12) | C32: Santosh
B33: GH to RP movement | C33: Santosh, Abhishek
B34: Parking at RP | C34: Santosh, Aditya
B35: Tea/Coffee setup at venue plus green room | C35: Swapneel
B36: Registration desk | C36: Key Event + Ruchi, Aditi
B37: Ground floor staff | C37: Puja, Deepawali
B38: VIP Elevator support | C38: Santosh, Aditya
B39: 8th floor staff | C39: Snehal
B40: 9th floor staff | C40: Sanjana, Elton, Joyita, Aditi
B41: Memento, gift arrangement backstage | C41: Jeenal
B42: Ushers | C42: Key Event, Jeenal, Rachana
... B63: VIP Handling overall | C63: Puja

Sheet Attendee List
B2: Sr. No | C2: Name | D2: Institute | E2: Hub | F2: Email | G2: Tag
B3: 1 | C3: Dr. Akshay Naik | D3: Indian Institute of Science Bangalore | E3: IIT Bombay | F3: anaik@iisc.ac.in | G3: PI
B4: 2 | C4: Dr. Akshay Singh | D4: Indian Institute of Science Bangalore | E4: IISc Bangalore | F4: aksy@iisc.ac.in | G4: PI
B5: 3 | C5: Dr. Amitangshu Pal | D5: Indian Institute of Technology Kanpur | E5: IIT Bombay | F5: amitangshu@cse.iitk.ac.in | G5: PI
B6: 4 | C6: Dr. Anil Shaji | D6: Indian Institute of Science Education and Research Thiruvananthapuram | E6: IISc Bangalore | F6: shaji@iisertvm.ac.in | G6: PI
B7: 5 | C7: Dr. Anirban Mitra | D7: Indian Institute of Technology Roorkee | E7: IIT Delhi | F7: anirban.mitra@ph.iitr.ac.in | G7: PI
B8: 6 | C8: Dr. Ankur Raina | D8: Indian Institute of Science Education and Research Bhopal | E8: IIT Madras | F8: ankur@iiserb.ac.in | G8: PI
B9: 7 | C9: Dr. Anshul Jaiswal | D9: Indian Institute of Technology Roorkee | E9: IIT Madras | F9: anshul.jaiswal@ece.iitr.ac.in | G9: PI
B10: 8 | C10: Dr. Anshuman Kumar | D10: Indian Institute of Technology Bombay | E10: IIT Delhi | F10: anshuman.kumar@iitb.ac. in | G10: PI
B11: 9 | C11: Dr. Arijit Sharma | D11: Indian Institute of Technology Tirupati | E11: IIT Madras | F11: arijit@iittp.ac.in | G11: PI
B12: 10 | C12: Dr. Ashok K Mohapatra | D12: National Institue of Science Education and Research Bhubaneswar | E12: IISc Bangalore | F12: a.mohapatra@niser.ac.in | G12: PI
B13: 11 | C13: Dr. Awanish Pandey | D13: Indian Institute of Technology Delhi | E13: IISc Bangalore | F13: awanish@ee.iitd.ac.in | G13: PI
B14: 12 | C14: Dr. Baladitya Suri | D14: Indian Institute of Science Bangalore | E14: IISc Bangalore | F14: surib@iisc.ac.in | G14: PI
... B143: 141 | C143: Shubham Utreja | D143: Prenishq | E143: I-Hub QTF, IISER Pune | F143: shubhamutreja77@gmail.com | G143: Expo
B144: 142 | C144: Sunil Sud | D144: QuNu Labs Pvt Ltd | E144: I-Hub QTF, IISER Pune | G144: Expo
B145: 143 | C145: Arsh Ahmed | D145: QuNu Labs Pvt Ltd | E145: I-Hub QTF, IISER Pune | G145: Expo
B146: 144 | C146: Vamsi Krishna | D146: QpiAI Pvt Ltd | E146: I-Hub QTF, IISER Pune | F146: vamsi.k@qpiai.tech | G146: Expo
B147: 145 | C147: Firoz Tahashildar | D147: QpiAI Pvt Ltd | E147: I-Hub QTF, IISER Pune | F147: Firoz.t@qpiai.tech | G147: Expo
B148: 146 | C148: Devendra Mishra | D148: Quantum AI Global (QAIG) | E148: IIT Madras | F148: devendra.mishra@qulabs.ai | G148: Expo
B149: 147 | C149: Sanjay Chittore | D149: Quantum AI Global (QAIG) | E149: IIT Madras | F149: sanjay@thequantum.ai | G149: Expo
B150: 148 | C150: Ashutosh Singh | D150: IITM CDOT Samgnya Technologies Foundation | E150: IIT Madras | F150: ashutosh@ee.iitm.ac.in | G150: Expo
B151: 149 | C151: Anagha Gayatri M | D151: IITM CDOT Samgnya Technologies Foundation | E151: IIT Madras | F151: anaghagayathri@smail.iitm.ac.in | G151: Expo
B152: 150 | C152: Abhilash Kumar Das | D152: IITM CDOT Samgnya Technologies Foundation | E152: IIT Madras | F152: abhilashkd@iitbhilai.ac.in | G152: Expo
B153: 151 | C153: Anirudh Jaiswal | D153: IITM CDOT Samgnya Technologies Foundation | E153: IIT Madras | G153: Expo
B154: 152 | C154: Bhaskar Sarkar | D154: IITM CDOT Samgnya Technologies Foundation | E154: IIT Madras | F154: bhaskarsarkar1213@gmail.com | G154: Expo
B155: 153 | C155: Abhay Dulta | D155: IITM CDOT Samgnya Technologies Foundation | E155: IIT Madras | F155: phz228454@iitd.ac.in | G155: Expo
B156: 154 | C156: Shubham Prajapati | D156: Synergy Quantum | E156: IIT Madras | F156: shubham.prajapati@synergyquantum.in | G156: Expo
B157: 155 | C157: Snehal Sharma | D157: Synergy Quantum | E157: IIT Madras | F157: snehal@synergyquantum.in | G157: Expo
B158: 156 | C158: Aniket Nag | D158: Qmet Tech Foundation | E158: IIT Bombay | F158: aniketnag24@iitk.ac.in | G158: Expo
B159: 157 | C159: Pranay Mohta | D159: Qmet Tech Foundation | E159: IIT Bombay | F159: pmohta@iitk.ac.in | G159: Expo
B160: 158 | C160: Praveen Hegde | D160: Qmet Tech Foundation | E160: IIT Bombay | F160: p.hegde@physics.iitm.ac.in | G160: Expo
B161: 159 | C161: John Jesudasan | D161: Qmet Tech Foundation | E161: IIT Bombay | F161: johnj.tifr@gmail.com | G161: Expo
B162: 160 | C162: Pooja Gunjal | D162: Qmet Tech Foundation | E162: IIT Bombay | F162: poojagunjal1212@gmail.com | G162: Expo
B163: 161 | C163: Roopa J | D163: Qmet Tech Foundation | E163: IIT Bombay | F163: roopaj@iisc.ac.in | G163: Expo
B164: 162 | C164: Purna Pal | D164: Qmet Tech Foundation | E164: IIT Bombay | F164: purnapal@iisc.ac.in | G164: Expo
B165: 163 | C165: Shouvik Mukherjee | D165: Nostradamus | E165: IIT Bombay | F165: shouvik@qubeats.com | G165: Expo
... B217: 215 | C217: Prof. S Arunkumar | D217: Gandhi Institute of Technology and Management, Gandhinagar, Visakhapatnam, Andhra Pradesh | E217: Teaching Lab | F217: dean_cse@gitam.edu | G217: Teaching Lab
B218: 216 | C218: Prof. Ravindra Kumar Sinha | D218: Delhi Technological University | E218: Teaching Lab | F218: dr_rk_sinha@yahoo.com | G218: Teaching Lab | H218: name to be confirmed
B219: 217 | C219: Dr. Girish J | D219: GMR Institute of Technology, Rajam, Srikakulam, Andhra Pradesh | E219: Teaching Lab | F219: Dr.Girish.Jammigumpula@gmrgroup.in | G219: Teaching Lab
B220: 218 | C220: Dr.Sumalatha Lingamgunta | D220: University College of Engineering Kakinada, East Godavari, Kakinada, Andhra Pradesh | E220: Teaching Lab | F220: lsumalatha@jntucek.ac.in | G220: Teaching Lab
...

Sheet TECH EXPO BOOTH Details
A1: Sr. no. | B1: Name of the Hub | C1: Name on the Fascia | D1: Power Requirements | E1: Booth Fascia/ Name | F1: Team Member 1 Name - First Name | G1: Team Member 1 Name - Last Name | H1: Gender | I1: Email Address | J1: Phone Number | K1: Team Member 2 Name - First Name | L1: Team Member 2 Name - Last Name | M1: Gender | N1: Email Address | O1: Phone Number | P1: Upload Product/Technology Image (300 dpi) | Q1: Technology Focus | R1: Brief Description of Your Startup and Product (in 200 words)
A2: BANGALORE
A3: Booth 1 | B3: Foundation for QC Innovation IISc Bangalore | C3: Neutral atom and trapped ion quantum computer | D3: 2 | E3: Neutral atom and trapped ion quantum computer | F3: Saptarishi | G3: Chaudhuri | H3: Male | I3: srishic@rri.res.in | J3: (+91) 7259899430 | K3: Umakant | L3: Rapol | M3: Male | N3: umakant.rapol@iiserpune.ac.in | O3: (+91) 9689908421 | P3: https://www.jotform.com/uploads/Qmet/260672027148052/6494586702916808495/Display.png | Q3: Atom and ion based quantum computing | R3: Our technology consortium focuses on indigenously developing neutral atom and trapped ion based quantum computing platform. While two cloud accessible system will soon be operational and work towards demonstration of the technology readiness is ongoing, we also intend to productise both the full stack system as well as many peripheral components. During the AQC, there will be one 3D scaled down display unit of the actual set-up hosted at RRI + components developed at IISER Pune, NISER Bhubaneswar and IIT Roorkee and IIT Guwahati.
A4: Booth 2 | B4: Foundation for QC Innovation IISc Bangalore | C4: A Highly Scalable Quantum Computer using Silicon Qubits (sharing) | D4: 3 X 220V | E4: A Highly Scalable Quantum Computer using Silicon Qubits (sharing) | F4: Pulak (also part of poster) | G4: Ghoshal | H4: Male | I4: eez248406@ee.iitd.ac.in | J4: (+91) 7290804546 | K4: Deepesh (also part of poster) | L4: Sharma | M4: Male | N4: deepesh.sharma@ee.iitd.ac.in | O4: (+91) 9858911301 | P4: https://www.jotform.com/uploads/Qmet/260672027148052/6495553635606105708/TG3-IITD-Quantum-Computer-Schematic.jpg | Q4: Quantum Computing | R4: To achieve a beyond NISQ (>1000 qubits) quantum computer, high density qubits, passives, and wiring are essential. Silicon CMOS process has the optimum BEOL for such work. With minor tweaks in standard CMOS, a derivative process for fabrication of quantum dot-based qubits can be created, and an all-Silicon Quantum Computer can be realized. In this Technical Group (TG3), we are developing the system at all levels, starting from system-level and then going down to the chip and qubit levels. Our mission objective is to demonstrate a working quantum computer with 50 qubits. | S4: To be merged with Cryogenic electronics for spin qubits
B5: Foundation for QC Innovation IISc Bangalore | C5: Cryogenic Electronics for Spin qubits (sharing) | D5: NA | E5: Cryogenic Electronics for Spin qubits (sharing) | F5: Rajat (also part of poster) | G5: Bharadwaj | H5: Male | I5: rajat21@iisertvm.ac.in | J5: (+91) 9933832246 | K5: Varsha | L5: Jangir | M5: Female | N5: 204120010@iitb.ac.in | P5: https://www.jotform.com/uploads/Qmet/260672027148052/6496502828185510048/nqm%20sub-low_8300.png | Q5: Silicon Quantum Dot Spin Qubits | R5: A suite of advanced cryogenic and qubit-control devices designed to ensure high-fidelity signal integrity and effective noise suppression in quantum experiments. The Cryo Damp-24 is a 24-channel low-pass filter based on a copper powder-epoxy composite, offering a cut-off frequency of 300 MHz for efficient attenuation of high-frequency noise. The μ Shield-12 incorporates 12 isolated DC lines in a compact module, providing comparable filtering performance with enhanced isolation. The San Noise-25 device features a finite ground coplanar waveguide fabricated on sapphire with aluminium, enabling superior thermalization and achieving a cut-off frequency below 100 kHz. Complementing these, the Cryo Pass-L24 is a fully customizable, modular 24-channel cryogenic low-pass filter. For qubit control, the Q-Nest provides a modular PCB system enclosed within a shielding enclosure, supporting 24 DC lines, 8 ohmic lines, and integrated passive filtering. Finally, the Q-CARD-24080601 is a versatile qubit control and readout platform incorporating DC, ohmic, RF, and readout lines, along with environmental shielding, LED integration, and ESD protection mechanisms for robust and reliable operation.
A6: Booth 3 | B6: Foundation for QC Innovation IISc Bangalore | C6: 6 qubit photonic system (sharing) | D6: 4 socket, 10Amp 240V | E6: 6 qubit photonic system (sharing) | F6: Sujai | G6: Matta | H6: Male | I6: sujaimatta@iisc.ac.in | J6: (+91) 9491238120 | K6: Soumya | L6: Asokan | M6: Female | N6: soumyaasokan@iisc.ac.in | O6: (+91) 9567246448 | P6: https://www.jotform.com/uploads/Qmet/260672027148052/6496277264281228497/6qubit-QC.png | Q6: Photonic Quantum Computing | R6: It's a device developed at Photonic Quantum Computing TG at IISc. A 6-qubit photonic system with provision for implementing 4 two-qubit gates, 4 single-qubit gates, and generating a 6-qubit maximally entangled state. Image is a representation; it will be packaged.
B7: Foundation for QC Innovation IISc Bangalore | C7: Photonics Quantum Processor 9(sharing) | D7: No | E7: Photonics Quantum Processor 9(sharing) | F7: Shankar Kumar | G7: Selvaraja | H7: Male | I7: shankarks@iisc.ac.in | J7: (91) 9481283513 | P7: https://www.jotform.com/uploads/Qmet/260672027148052/6502142416158167143/Picture1.png | Q7: Photonics quantum processor | R7: Display of a model of a photonics quantum processor, Wafer display with photonic circuit, single photon emitter chip and testing jig display. | S7: 6.50214e+18
A8: Booth 4 | B8: Foundation for QC Innovation IISc Bangalore | C8: Control & Measurement Electronics for Superconducting Qubits | D8: 4 / 220V | E8: Control & Measurement Electronics for Superconducting Qubits | F8: Shantharam | G8: Kalipatnapu | H8: Male | I8: shantharamk@iisc.ac.in | J8: (+91) 8972246283 | K8: Venkata Pavan Kalyan | L8: Missula | M8: Male | N8: pavkalyan100@gmail.com | O8: (+91) 7294874910 | P8: https://www.jotform.com/uploads/Qmet/260672027148052/6495812735188358844/ConElec-SuperCQ.jpg | Q8: Superconducting Qubits | R8: We will display prototypes of FPGA based control & measurement electronics, cryogenic filters , and Josephson Parametric Amplifiers
A10: PUNE
A11: Sr. no. | B11: Name of the Hub | C11: Name on the Fascia | D11: Power Requirements | E11: Booth Fascia/ Name | F11: Team Member 1 Name - First Name | G11: Team Member 1 Name - Last Name | H11: Gender | I11: Email Address | J11: Phone Number | K11: Team Member 2 Name - First Name | L11: Team Member 2 Name - Last Name | M11: Gender | N11: Email Address | O11: Phone Number | P11: Upload Product/Technology Image (300 dpi) | Q11: Technology Focus | R11: Brief Description of Your Startup and Product (in 200 words)
A12: Booth 1 | B12: I-Hub QTF, IISER Pune | C12: Quanastra Pvt Ltd | D12: 2 | E12: Quanastra Pvt Ltd | F12: Vidur | G12: Raj | H12: Male | I12: vidur.raj@quanastra.com | J12: (+91) 9205771590 | K12: Anand | L12: Mohan | M12: Male | N12: s21027@students.iitmandi.ac.in | O12: (+91) 7678310811 | P12: https://www.jotform.com/uploads/Qmet/260672027148052/6495604869251620860/Picture1.png | Q12: Quantum Sensing | R12: Quanastra is a deep-tech startup operating at the forefront of quantum and photonics technologies, with a long-term vision to establish itself as a hub for quantum and photonics chip manufacturing. In near term, we are developing Single photon detectors, and associated hardware under national Quantum Mission. Some of our market ready products: UHV Fiber Feedthrough, DC cryoelectronic wiring, High Precision Microampere Current. Some of these we will be showcasing at the IIT Bombay Expo. | S12: 6.4956e+18
B13: I-Hub QTF, IISER Pune | C13: SCI-COM SOFTWARE INDIA PRIVATE LIMITED | D13: 4 | E13: SCI-COM SOFTWARE INDIA PRIVATE LIMITED | F13: Vaishnavi | G13: Vaichal | H13: Female | I13: vaishnavi.vaichal@scicomsoftware.com | J13: (+91) 7768074457 | K13: Suhas | L13: Kulkarni | M13: Male | N13: suhas.kulkarni@scicomsoftware.com | O13: (+91) 9403768214 | P13: https://www.jotform.com/uploads/Qmet/260672027148052/6495522526427438722/IMG_1743.JPEG | Q13: Instrumentation and Control for Quantum Technology Research and Development | R13: SCI-COM was founded in 1998 and has been working in areas such as signal and image processing, high-speed FPGA electronics, Digital Signal Processing and microcontroller-based boards, RF modules, power distribution modules (industrial and MIL-grade), software development, and embedded systems. We also provide independent verification and validation services for DRDO and other PSUs. iQUANTROL-1.0 is an Instrumentation and Control Unit to be used in Laboratory Setups for Quantum Technology Research and Development. This unit provides a host computer based GUI Application to configure different Instrumentation and Control parameters required by the Laboratory Setup. It has a high performance electronics platform interfaced over ethernet with the host PC to perform real time functions such as high speed signal generation, high speed signal sampling/acquisition, signal processing for signal features estimation, control loops implementation through embedded software and diagnostics/log reports.
A14: Booth 2 | B14: I-Hub QTF, IISER Pune | C14: Prenishq | D14: 4 | E14: Prenishq | F14: Bodhaditya | G14: Santra | H14: Male | I14: bodhaditya.santra@gmail.com | J14: (+91) 7047373599 | K14: Shubham | L14: Utreja | M14: Male | N14: shubhamutreja77@gmail.com | O14: (+91) 9829825823 | P14: https://www.jotform.com/uploads/Qmet/260672027148052/6495799308513351203/Prenishq%20Laser%20Launch%20flyer%20revised.pdf | Q14: High precision diode laser for quantum computing, sensing, metrology and communication | R14: Prenishq Pvt. Ltd., a spin-off from IIT Delhi and supported by the National Quantum Mission manufactures high precision diode lasers for quantum computing, sensing, metrology and communication. The Prenishq Opal Laser is a high-performance, precision-engineered system designed for quantum research, education, and advanced experiments. With exceptional beam quality, stability, and long-term durability, it’s ideal for seamless integration into scientific and quantum equipment. These lasers stand out for its low cost of ownership, ease of installation, minimal maintenance, light weight, and assured availability to promise. Combining performance, efficiency, and accessibility, Prenishq’s lasers position India at the forefront of laser technology and quantum innovation.
A15: Booth 3 | B15: I-Hub QTF, IISER Pune | C15: QuNu Labs Private Limited | D15: 2 | E15: QuNu Labs Private Limited | F15: Sunil | G15: Sud | H15: Male | J15: (+91) 7899791155 | K15: Arsh Ahmed | M15: Male | P15: https://www.jotform.com/uploads/Qmet/260672027148052/6496353206325463976/QNu%20Product.png | Q15: Quantum Communication | R15: QNu Labs is India’s pioneering quantum cybersecurity company focused on building technologies that protect digital infrastructure from future quantum computing threats. Founded in 2016 and incubated at IIT Madras Research Park, the company’s mission is to make India self-reliant in digital security while enabling a global transition toward quantum-safe communication. As quantum computing advances, today’s encryption methods such as RSA and ECC will become vulnerable, posing serious risks to governments, financial systems, telecom networks, and critical infrastructure. QNu Labs addresses this challenge through an indigenous ecosystem of quantum-safe technologies that combine hardware and software innovations. Its portfolio includes Armos (Quantum Key Distribution), Tropos (Quantum Random Number Generator), the QShield crypto-agile security platform, and quantum communication chips for secure edge systems. QNu’s hybrid architecture integrates quantum physics-based security with post-quantum cryptography, enabling organizations to transition to quantum-safe infrastructure without replacing existing systems. These solutions secure communications, data, and identity across sectors such as defence, telecom, banking, and government. With multiple patents, defence validations, and real-world deployments—including long-distance quantum networks—QNu Labs is positioning India at the forefront of the emerging quantum security era, enabling governments and enterprises to achieve digital sovereignty, long-term data protection, and resilient cybersecurity for the post-quantum world.
A16: Booth 4 | B16: I-Hub QTF, IISER Pune | C16: QpiAI India Private Limited | D16: 2 sockets 220v | E16: QpiAI India Private Limited | F16: Vamsi | G16: Krishna | H16: Male | I16: vamsi.k@qpiai.tech | J16: (91) 7895873873 | K16: Firoz | L16: Tahashildar | M16: Male | N16: Firoz.t@qpiai.tech | O16: () 7353155091 | P16: https://www.jotform.com/uploads/Qmet/260672027148052/6500608394918164434/IMG_1064%20%281%29.jpeg | Q16: Quantum error correction | R16: QpiAI QEC is developed to enhance qubit reliability and system performance. Using advanced algorithms , it detects and corrects errors in real time, improving fidelity and extending coherence time of physical qubits. The system implements a distance-5 rotated surface code using 49 physical qubits. Each decoder instance runs on a single QpiAI Kaveri QPU, which provides 64 qubits, allowing one decoder instance per chip. The architecture is optimized to support efficient decoding and integration with existing quantum hardware. | S16: 6.50061e+18
A19: MADRAS
A20: Sr. no. | B20: Name of the Hub | C20: Name on the Fascia | D20: Power Requirements | E20: Booth Fascia/ Name | F20: Team Member 1 Name - First Name | G20: Team Member 1 Name - Last Name | H20: Gender | I20: Email Address | J20: Phone Number | K20: Team Member 2 Name - First Name | L20: Team Member 2 Name - Last Name | M20: Gender | N20: Email Address | O20: Phone Number | P20: Upload Product/Technology Image (300 dpi) | Q20: Technology Focus | R20: Brief Description of Your Startup and Product (in 200 words)
A21: Booth 1 | B21: IITM CDOT Samgnya Technologies Foundation at IIT Madras | C21: Quantum AI Global (QAIG) | D21: 3 | E21: Quantum AI Global (QAIG) | F21: Devendra | G21: Mishra | H21: Male | I21: devendra.mishra@qulabs.ai | J21: (+91) 7398725444 | K21: Sanjay | L21: Chittore | M21: Male | N21: sanjay@thequantum.ai | O21: (+91) 9700699999 | P21: https://www.jotform.com/uploads/Qmet/260672027148052/6506955152498788044/QAIG.jpg | Q21: Quantum Key Distribution & Q-Memory | R21: Enhancing QAIG’s atomic memory system to be compatible with telecom wavelengths significantly broadens its applicability across quantum communication systems. It enables quantum key distribution (QKD) and quantum networking over existing fiber links by shifting photons into the low-loss telecom band. | S21: 6.50696e+18
A22: Booth 2 | B22: IITM CDOT Samgnya Technologies Foundation at IIT Madras | C22: QuiLA - TG! | D22: 4 | E22: QuiLA - TG! | F22: Ashutosh | G22: Singh | H22: Male | I22: ashutosh@ee.iitm.ac.in | J22: (+91) 9122866323 | K22: Anagha Gayatri | L22: M | M22: Female | N22: anaghagayathri@smail.iitm.ac.in | O22: (+91) 8754325797 | P22: https://www.jotform.com/uploads/Qmet/260672027148052/6502691282497432140/QuiLA.jpg | Q22: QuiLA | R22: Working under TG-1 with Prof. Anil Prabhakar | S22: 6.50269e+18
B23: IITM CDOT Samgnya Technologies Foundation at IIT Madras | C23: Settlor Lab, IIT Kanpur | D23: 3 | F23: Abhilash Kumar | G23: Das | H23: Male | I23: abhilashkd@iitbhilai.ac.in | J23: (+91) 8617844701 | P23: https://www.jotform.com/uploads/Qmet/260672027148052/6501556695026954019/CWLite.jpeg | Q23: Side Channel Analysis | R23: CRYSTALS-Kyber is a CCA2-secure key encapsulation mechanism defined over the quotient ring ( Z_q[x]/(X^n + 1) ), with parameters ( q = 3329 ) and ( n = 256 ). It has three variants—Kyber-512, Kyber-768, and Kyber-1024—based on different security levels. The scheme consists of three main operations: key generation, encapsulation, and decapsulation. Although the algorithm itself is secure, its hardware implementation is vulnerable to side-channel attacks due to inherent physical leakage. This work demonstrates a successful attack using Correlation Power Analysis (CPA). For trace acquisition, ChipWhisperer CW305 was used along with ChipWhisperer Lite, enabling efficient and cost-effective power trace collection. A total of 50,000 random and 50,000 fixed traces were captured to perform TVLA (Test Vector Leakage Assessment). The results showed TVLA values consistently above 4.5, often exceeding 20 and even reaching beyond 40, confirming significant leakage. The attack targets the decapsulation step, specifically the computation ( v - s^T u ), focusing on the point-wise multiplication ( s^T . u ). A chosen ciphertext attack was conducted on the hardware implementation, which operates with a latency of 256 clock cycles. Approximately 10,000 traces were required to recover one coefficient of the secret key, resulting in about 280,000 traces to extract the full key. | S23: 6.50156e+18
B24: IITM CDOT Samgnya Technologies Foundation at IIT Madras | C24: IIT Bhilai: Fault Injection Attack on Kyber-768 | D24: 2 sockets, 220V | H24: Male | J24: (+91) 9362672150 | K24: Anirudh | L24: Jaiswal | M24: Male | O24: (+91) 7439215216 | P24: https://www.jotform.com/uploads/Qmet/260672027148052/6502483482521778987/cw-lite-32.jpg.jpeg | Q24: Clock glitching | R24: The team will demonstrate a practical fault-injection attack (published in ASIACRYPT 2021 by Xagawa et al.) on Key Encapsulation Mechanism (CRYSTALS-Kyber) using ChipWhisperer Lite Part - I. The demo is followed by the recovery of long-term secret. First, the board specifications are configured, the firmware is compiled, and the clock glitching parameters are set before running the main glitching script. The process then involves sweeping through the maximum ranges of the parameters, namely width (w) and offset (o). By analyzing combinations of (w, o, ext_o), instances of crashes and resets can be identified, which confirm that the glitch is affecting the execution pipeline of the algorithm. The parameter ext_o plays a crucial role, as it determines when the capture board inserts the glitch after receiving the trigger, allowing precise control of the glitch timing at the nanosecond level within a clock cycle. As a result, the expected outcomes include downgrading the security of Kyber-768 from CCA-secure to CPA-secure through fault injection, and obtaining a 32-byte shared secret K for any crafted ciphertext. | S24: 6.50248e+18
A25: Booth 3 | B25: IITM CDOT Samgnya Technologies Foundation at IIT Madras | C25: TAHQEECAT | D25: 3 | E25: TAHQEECAT | F25: Bhaskar | G25: Sarkar | H25: Male | I25: bkanseri@physics.iitd.ac.in | J25: (+91) 9811026412 | K25: Abhay | L25: Dutta | M25: Male | N25: phz228454@iitd.ac.in | O25: (+91) 9811026412 | P25: https://www.jotform.com/uploads/Qmet/260672027148052/6506962512498199842/TAHQEECAT.jpg | Q25: Entangled photon source at telecom wavelength | R25: Trusted-node Free Hybrid Quantum Secure Communication Network (TAHQEECAT) | S25: 6.50696e+18
A26: Booth 4 | B26: IITM CDOT Samgnya Technologies Foundation at IIT Madras | C26: Synergy Quantum | D26: 3 | E26: Synergy Quantum | F26: Shubham | G26: Prajapati | H26: Male | I26: shubham.prajapati@synergyquantum.in | J26: (+91) 9818987581 | K26: Snehal | L26: Sharma | M26: Female | N26: snehal@synergyquantum.in | O26: (+91) 7276249440 | P26: https://www.jotform.com/uploads/Qmet/260672027148052/6506943952498197516/SynergyQuantum.jpg | Q26: PQC-Secure 5G Core | R26: We are focused on Post Quantum Cryptography and we are currently incubated with Samgnya on Quantum Secure 5GCore | S26: 6.50694e+18
A31: BOMBAY
A32: Sr. no. | B32: Name of the Hub | C32: Name on the Fascia | D32: Power Requirements | E32: Booth Fascia/ Name | F32: Team Member 1 Name - First Name | G32: Team Member 1 Name - Last Name | H32: Gender | I32: Email Address | J32: Phone Number | K32: Team Member 2 Name - First Name | L32: Team Member 2 Name - Last Name | M32: Gender | N32: Email Address | O32: Phone Number | P32: Upload Product/Technology Image (300 dpi) | Q32: Technology Focus | R32: Brief Description of Your Startup and Product (in 200 words)
A33: Booth 1 | B33: Qmet Tech Foundation at IIT Bombay | C33: Quantum Imaging Techncial Group, IIT Kanpur | D33: One Socket (5/15 Amp) for Image Rotator and Two Sockets (5/15 Amp) | E33: Quantum Imaging Techncial Group, IIT Kanpur | F33: Aniket | G33: Nag | H33: Male | I33: aniketnag24@iitk.ac.in | J33: (+91) 8972799320 | K33: Pranay (also in poster) | L33: Mohta | M33: Male | N33: pmohta@iitk.ac.in | O33: () 7980625513 | P33: https://www.jotform.com/uploads/Qmet/260672027148052/6501594666024789905/coherence%20detector.jpg https://www.jotform.com/uploads/Qmet/260672027148052/6501594666024789905/image%20rotator.jpg | Q33: Quantum imaging and high-dimensional quantum information | R33: 1. Image Rotator: This can be used for rotating any wavefront with ( Angular Deviation < 1 milli-radian and Mean Polarisation Change < 5%). The commercially available IRs have angular deviation > 100 milli-radian and Mean Polarisation Changes are > 40%). This can be commercialised and will have application in high-dimensional classical and quantum information and quantum imaging. 2. Spatial Coherence Detector: Device for measuring spatial coherence. This is a detector for measuring complex spatial coherence of light, with more than 95% fidelity in the presence of background noise of signal to noise ratio (SNR) as low as 1/10. This is a crucial device for noise-resilient imaging. | S33: 6.50159e+18
A34: Booth 2 | B34: Qmet Tech Foundation at IIT Bombay | C34: - Magnetic microscope based on NV- centers in diamond (sharing) | D34: 15A | F34: Prasobh | G34: Padmanabhan | H34: Male | I34: prasobh.padmanabhan@qmettech.com | J34: (+91) 8073277036 | K34: Shishir | L34: Dasika | M34: Male | N34: shishir.dasika@qmettech.com | O34: () 73820336590 | P34: https://www.jotform.com/uploads/Qmet/260672027148052/6502451804853886749/QDM_Image.jpg | Q34: NV Centre Sensing | R34: The Quantum Diamond Microscopes (QDM) works in room temperature and generates magnetic field maps, which can be used for the detection of Hardware trojans. The QDM maps the magnetic field of a chip while it processes the data. By comparing this map to a trusted chip, defense analysts can spot tiny, unauthorized circuits that shouldn't be there. Similarly, these magnetic field maps can be used for the defect detection of chips. They can also help in non-destructively reverse engineering the chips, by revealing the internal architecture. Qmet’s quantum diamond microscope delivers high-performance magnetic imaging by combining a magnetic field sensitivity of 0.7 µT/√Hz with a spatial resolution of 1 µm. This configuration allows for the detection of subtle magnetic field variations while maintaining the ability to resolve localized features at the micron scale. The system features a 100 µm field of view, enabling simultaneous wide-field characterization of magnetic textures or current distributions across a significant sample area. Side illumination, Normal illumination and Cryogenic setup of QDM are available in the lab. Technical specifications: Sensitivity: 0.7 µT/√Hz, Resolution: 1 um, FOV: 100 µm | S34: 6.50245e+18
B35: Qmet Tech Foundation at IIT Bombay | C35: Quantum Diamond Magnetometer | D35: 15A | F35: Vinayak | G35: Rane | H35: Male | I35: vinayak.rane@qmettech.com | J35: (+91) 9867236112 | K35: Abhijeet | L35: Ghodgaonkar | M35: Male | N35: abhijeet.ghodgaonkar@qmettech.com | O35: () 9962648741 | P35: https://www.jotform.com/uploads/Qmet/260672027148052/6502460634853052624/MagPI_Image_8231.jpg | Q35: NV Centre Sensing | R35: Quantum magnetometers offer a potential alternative for aerial navigation in environments where GPS is unreliable. By utilizing the Earth’s magnetic field, these sensors provide a passive navigation source that is difficult to defeat. While the technology is still maturing, it holds specific value for defense and space sectors requiring positioning redundancy in contested or remote areas. Additionally, the high sensitivity of these devices may improve the detection of localized magnetic anomalies, such as those generated by submerged vessels or metallic structures. Ultimately, integrating quantum magnetometry into existing sensor suites could provide a potential solution to vulnerabilities of satellite-dependent systems. Qmet’s magnetometer offers high-precision magnetic field characterization with a sensitivity of 0.7 nT/√Hz and full vector measurement capabilities. Operating within a bandwidth of DC to 0.1 kHz, the system is optimized for stable static measurements and low-frequency signal detection. It features an expansive dynamic range spanning from pT to mT levels, allowing it to transition seamlessly between measuring subtle fluctuations and strong magnetic environments. Consuming 50 W of power, the device is designed to maintain robust performance for industrial or laboratory-grade applications. We have already working on improving the form factor to make it compatible with a variety of mobile applications. Technical specifications: Sensitivity: 0.7 pT/√Hz Bandwidth: DC – 0.1 kHz, Dynamic Range: pT to mT, Power: 50 W, Vector capability: Yes | S35: 6.50246e+18
B36: Qmet Tech Foundation at IIT Bombay | C36: Quantum Diamond Magnetometer (sharing) | D36: 4 sockets with 230 V Ac | F36: Vinayak | G36: Rane | H36: Male | I36: vinaya.rane@qmettech.com | J36: (+91) 9867236112 | K36: Abhijeet | L36: Ghodgaonkar | M36: Male | N36: abhijeet.ghodgaonkar@qmettech.com | O36: (+91) 9962648741 | P36: https://www.jotform.com/uploads/Qmet/260672027148052/6502478419741009952/MagPI_Photo_2898.JPG | Q36: NV Centre Sensing | R36: Quantum magnetometers offer a potential alternative for aerial navigation in environments where GPS is unreliable. By utilizing the Earth’s magnetic field, these sensors provide a passive navigation source that is difficult to defeat. While the technology is still maturing, it holds specific value for defense and space sectors requiring positioning redundancy in contested or remote areas. Additionally, the high sensitivity of these devices may improve the detection of localized magnetic anomalies, such as those generated by submerged vessels or metallic structures. Ultimately, integrating quantum magnetometry into existing sensor suites could provide a potential solution to vulnerabilities of satellite-dependent systems. Qmet’s magnetometer offers high-precision magnetic field characterization with a sensitivity of 0.7 nT/√Hz and full vector measurement capabilities. Operating within a bandwidth of DC to 0.1 kHz, the system is optimized for stable static measurements and low-frequency signal detection. It features an expansive dynamic range spanning from pT to mT levels, allowing it to transition seamlessly between measuring subtle fluctuations and strong magnetic environments. Consuming 50 W of power, the device is designed to maintain robust performance for industrial or laboratory-grade applications. We have already working on improving the form factor to make it compatible with a variety of mobile applications. Technical specifications: Sensitivity: 0.7 nT/√Hz Bandwidth: DC – 0.1 kHz, Dynamic Range: pT to mT, Power: 50 W, Vector capability: Yes | S36: 6.50248e+18
B37: Qmet Tech Foundation at IIT Bombay | C37: Lab grown diamond | D37: 0 | F37: M. S. Ramachandra Rao | G37: M | H37: Male | I37: msrrao@iitm.ac.in | J37: (+91) 7397316470 | K37: Rajeev | L37: Gandhi | M37: Male | P37: https://www.jotform.com/uploads/Qmet/260672027148052/6506911136333847079/DiamondSamples_RP_3526.png | Q37: NV centre sensing | R37: These are high-quality high purity diamond samples made by India Centre for Labgrown Diamonds (InCent LGD) at IIT Madras. As part of the centre we also have characterisation facilities that researchers and companies can access. | S37: 6.50691e+18
B38: Qmet Tech Foundation at IIT Bombay | C38: Control electronics (SPELLab, IITM) | D38: 1 | F38: Suthinthraraj | G38: B | H38: Male | I38: ep23b052@smail.iitm.ac.in | J38: (+91) 7010895601 | K38: Aadit | L38: Chugh | M38: Male | N38: ep22b019@smail.iitm.ac.in | P38: https://www.jotform.com/uploads/Qmet/260672027148052/6506926056339673188/control%20electronics.jpg | Q38: Control electronics for NV sensing but can be useful for quantum tech too | R38: These are products we are developing under the NQM mission in the SPELLab (PI: Praveen Bhallamudi). These are control electronics products that include: Synchronisation pulse generators for quantum control sequences, frequency detectors (alternate to zero cross type), PLL. We have PoCs for these. We are currently working on developing digital lock-in with PLL and PID controllers for scanned probe controllers. | S38: 6.50693e+18
B39: Qmet Tech Foundation at IIT Bombay | C39: ISMO Biophotonics | D39: 0 | F39: Ikram | G39: Khan | H39: Male | I39: Ikram@ismobiophotonics.com | J39: (+91) 95515 59159 | K39: Praveen | L39: Hegde | M39: Male | N39: p.hegde@physics.iitm.ac.in | P39: https://www.jotform.com/uploads/Qmet/260672027148052/6506935246337613220/ISMO%20Balanced%20detector.jpg | Q39: Photodetectors for quantum technologies | R39: ISMO Biophotonics aims at the development of cutting edge medical devices. As part of our work with optics, they are also developing photodetectors in conjunction with SPELLab at IITM. They are being used in NV sensing and other experiments. (https://ismobiophotonics.com) | S39: 6.50694e+18
B40: Qmet Tech Foundation at IIT Bombay | C40: Quazartech | D40: No | F40: Joshua | G40: Mattew | H40: Male | I40: support@quazartech.com | J40: (+91) 1141828927 | K40: Deshdeep | L40: Sahdev | M40: Male | P40: https://www.jotform.com/uploads/Qmet/260672027148052/6506951446337177374/QT-AFM.jpg | Q40: Scanned probe microscope and probes | R40: Quazar Tech have developed a quartz tuning fork (QTF)- based AFM system that is highly cost effective (~3X less price) and is well suited for the development of NV-diamond based scanned probe microscopes. They also make the QTF scanning probes as well. Their first AFM system has just been successfully installed at SPELLab at IITM and is performed well during testing with standardised samples. | S40: 6.50695e+18
B41: Qmet Tech Foundation at IIT Bombay | C41: TIFR-QMet cryogenic inertial positioner | D41: four 5 amps power point with switches. | F41: John | G41: Jesudasan | H41: Male | I41: johnj.tifr@gmail.com | J41: (+91) 9869279569 | K41: Pooja | L41: Gunjal | M41: Female | N41: poojagunjal1212@gmail.com | O41: (+91) 8010538448 | P41: https://www.jotform.com/uploads/Qmet/260672027148052/6506815553427022903/Picsart_26-03-30_17-33-41-145.jpg | Q41: we develop a compact, low cost Nanopositioning system capable of precise motion at nanometer scale over millimetre ranges and operating at cryogenic temperature (down to 2.0 K) | R41: The inertial nanopositioner has a very compact, lightweight and simple construction and operates using a slip-stick mechanism driven by piezoelectric actuation. The basic design has three principal parts. The active part is a piezoelectric ceramic stack, glued to a moving stage on one side and the other side is glued to a triangular metallic monorail, acting as the guiding rod. The system is supported by a fully automated, microcontroller-based control electronics with computer interfacing. Sawtooth waveform with an amplitude of 6 to 60 volts is essential in driving the piezoelectric element. We generate a sawtooth waveform using analog output from a microcontroller and OP-amp based amplifier. We use LabVIEW or python-based user interface to control the mode of operation, amplitude and frequency of the sawtooth. X and Y nanopositioner can be stack on the Z-nanopositioner. Currently fabricated two stacks of X-Y-Z nanopositioners, each with footprints of 15 × 15 mm² and 24 × 24 mm², respectively. Also the position of the nanopositioner can be sensed with an Encoder module which is incorporated within the nanopositioner. | S41: 6.50682e+18
A42: Booth 3 | B42: Qmet Tech Foundation at IIT Bombay | C42: V-PAR Microsystems Pvt. Ltd. | D42: 2 sockets and One monitor | E42: V-PAR Microsystems Pvt. Ltd. | F42: Roopa | G42: J | H42: Female | I42: roopaj@iisc.ac.in | J42: (91) 9739815213 | K42: Purna | L42: Pal | M42: Female | N42: purnapal@iisc.ac.in | O42: (91) 8617013318 | P42: https://www.jotform.com/uploads/Qmet/260672027148052/6504131075184348606/Vapor%20cell-Tech.jpeg | Q42: Chip-Scale Atomic Metrology | R42: Our startup is a deep-tech venture focused on the indigenization of high-performance MEMS alkali vapor cells, the essential "physics package" for miniaturized quantum technologies. By moving away from traditional, manual glass-blowing techniques toward automated, wafer-level semiconductor batch fabrication, we produce hermetically sealed Rubidium and Cesium cells at a scale and precision previously unavailable in the domestic market. Our core product enables the transition of quantum sensors from bulky laboratory setups to chip-scale components, specifically targeting the Strategic Sector for ISRO and DRDO's GPS-denied navigation and satellite timing requirements. Beyond defense, we provide the hardware foundation for 5G/6G network synchronization and advanced medical brain imaging via Optically Pumped Magnetometers (OPMs). Based within the IISc-CeNSE ecosystem, we bridge the critical gap between complex quantum physics and industrial mass production. Our mission is to secure a sovereign, ITAR-free supply chain for the global quantum metrology market, offering high-reliability, low-power sensing solutions that are ready for seamless integration into the next generation of aerospace, telecommunications, and healthcare infrastructure. | S42: 6.50413e+18
A43: Booth 4 | B43: Qmet Tech Foundation at IIT Bombay | C43: QuBeats | D43: 2 sockets/ 220 VAC | E43: QuBeats | F43: Shouvik | G43: Mukherjee | H43: Male | I43: shouvik@qubeats.com | J43: (+91) 8777488192 | K43: Pritam | L43: Das | M43: Male | N43: pritam@qubeats.com
A46: DELHI
A47: Sr. no. | B47: Name of the Hub | C47: Name on the Fascia | D47: Power Requirements | E47: Booth Fascia/ Name | F47: Team Member 1 Name - First Name | G47: Team Member 1 Name - Last Name | H47: Gender | I47: Email Address | J47: Phone Number | K47: Team Member 2 Name - First Name | L47: Team Member 2 Name - Last Name | M47: Gender | N47: Email Address | O47: Phone Number | P47: Upload Product/Technology Image (300 dpi) | Q47: Technology Focus | R47: Brief Description of Your Startup and Product (in 200 words)
A48: Booth 1 | B48: QMD Foundation at IIT Delhi | C48: III-V Semiconductor based LNA and SPAD | D48: 3/220 | E48: III-V Semiconductor based LNA and SPAD | F48: Rajendra | G48: Singh | H48: Male | I48: rsingh@physics.iitd.ac.in | J48: (91) 9582774442 | K48: Samaresh | L48: Das | M48: Male | N48: samareshdas@care.iitd.ac.in | O48: (91) 9899130814 | P48: https://www.jotform.com/uploads/Qmet/260672027148052/6501600758606575847/Picture2.jpg | Q48: Quantum Materials and Devices | R48: Low Noise Amplifier (LNA) • High-performance LNAs using SiGe technology with a COTS transistor tested at room temperature • Achieved noise figure < 1.4 dB over 1.5–4.5 GHz • InP-based dies introduced to reduce noise figure and improve input matching • Operating frequency range: 1–5 GHz • Two-stage cascaded and balanced LNAs investigated • Devices use 200 μm and 150 μm gate-width InP HEMTs • Cascaded LNA performance (296 K, unconditionally stable): o Gain: 25.4 dB o Noise figure: < 0.9 dB o Input return loss: > 5.6 dB • Achieved performance parameters: o Return loss: > 15 dB o Gain: 24.7 dB o Noise figure: < 1.18 dB Single-Photon Avalanche Detector (SPAD) • Device structure: InGaAs/InP SAGCM SPAD • Layers: absorption, grading, charge, and multiplication regions • TCAD simulations used to study: o Charge layer engineering o Zn diffusion effects o Breakdown characteristics • Electric field confined in multiplication region (~3.5 × 10⁵ V/cm) • Absorption region maintains low electric field (< 1 × 10⁵ V/cm) • Device designed for 1550 nm wavelength (telecommunication band) • Fabrication includes hard mask design for planar and mesa SPADs • Integrated simulation and fabrication improve: o Photon Detection Efficiency (PDE) o Noise performance | S48: 6.5016e+18
A49: Booth 2 | B49: QMD Foundation at IIT Delhi | C49: 2D Photon Emitter & Avalanche Detector Arrays | D49: 3/220V | E49: 2D Photon Emitter & Avalanche Detector Arrays | F49: Prof. Saurabh | G49: Lodha | H49: Male | I49: slodha@iitb.ac.in | J49: (+91) 9819927460 | K49: Prof. Anshuman | L49: Kumar | M49: Male | N49: anshuman.kumar@iitb.ac.in | O49: (+91) 9958713346 | P49: https://www.jotform.com/uploads/Qmet/260672027148052/6501616470659994834/2D%20Photon%20Emitter%20%26%20Detector%20Arrays.jpg | Q49: Qunatum Materials & Devices | R49: 1. India’s 1st (a) quantum emitter array chip and (b) submicron 2D Avalanche photodetector and. 2. Images and Schematics of (a) hBN based device with integrated nanocavity for optimized and (b) brightness WSe₂ flake based device with Ti/Pt/Au (5 nm/30 nm/100 nm) and Ti/Ni/Au (5 nm/30 nm/100 nm) contacts. 3. Optical images of (a) the device on Si/SiO2 substrate for potential application of large area arrays of SPE arrays and (b) an array of ALD grown MoS2 transistors transferred on a back gate Si/SiO2 substrate for potential application of large area arrays of APDs. | S49: 6.50162e+18
...

Sheet footfall
L1: Hardik
L2: sanjana
B3: Expo | C3: 25 | D3: 20/20 | L3: srishti
B4: Poster | C4: 29 | D4: 16/17 | L4: elton
B5: Student/JRF/SRF | C5: 24 | L5: ruchi
B6: PI | C6: 104 | D6: (including IISER Pune PD) | L6: aakash
B7: Qmet | C7: 28 | L7: rutuja
B8: DST / MGB/ MTRC | C8: 30 | L8: snehal
B9: CEO | C9: 5 | L9: swapneel
B10: Remaining Hubs Staff | C10: 10 | L10: wajid
B11: Announcements | C11: 29 | L11: deepawali
B12: Total | C12: =SUM(C3:C11) -> 284 | L12: rachana
L13: joyita
L14: santosh
L15: shishir
L16: prashobh
L17: vinayak
L18: abhijeet
L19: aditi
L20: pavithra
L21: jeenal
L22: heena
L23: nitin
L24: aditya
... L28: Puja

Sheet Registrations
A1: Submission Date | B1: Name - First Name | C1: Name - Last Name | D1: Category | E1: Name of the Hub/Institution | F1: Contact Number | G1: E-mail | H1: Designation | I1: Your Company/Institution | J1: City/Town | K1: Hub | L1: Corrected Hub values | M1: TG | N1: Correct TG Names | P1: PI Name
A2: 46079.852 | B2: Ankur | C2: Raina | D2: Academician/Researcher | E2: IISER BHOPAL | F2: (+91) 9900495182 | G2: ankur@iiserb.ac.in | H2: Assistant Professor | J2: Bhopal | K2: =VLOOKUP(G2,Dataset!F:H,2,0) -> IIT Madras | L2: IIT Madras | M2: =VLOOKUP(G2,Dataset!F:H,3,0) -> TAHQEECAT
A3: 46079.9 | B3: Neel Kanth | C3: Kundu | D3: Academician/Researcher | E3: Quantum Communications | F3: (+91) 9891901100 | G3: neelkanth@iitd.ac.in | H3: Assistant Professor | J3: New Delhi | K3: =VLOOKUP(G3,Dataset!F:H,2,0) -> IIT Madras | L3: IIT Madras | M3: =VLOOKUP(G3,Dataset!F:H,3,0) -> TAHQEECAT
A4: 46079.905 | B4: Veeresh Vidyadhar | C4: Deshpande | D4: Academician/Researcher | E4: Indian Institute of Technology Bombay | F4: (91) 9108878742 | G4: veeresh@gmail.com | H4: Associate Professor | J4: Mumbai | K4: =VLOOKUP(G4,Dataset!F:H,2,0) -> #N/A | L4: IIT Bombay|IISc Banglore | M4: =VLOOKUP(G4,Dataset!F:H,3,0) -> #N/A | N4: TG 1 Kasturi Saha | TG 5 Quantum Computers with superconducting qubits
A5: 46080.655 | B5: Ravikiran | C5: Yeleswarapu | D5: Academician/Researcher | E5: BITS-Pilani Hyderabad, HUB: Quantum Computing HUB,IISC | F5: (+91) 8008547840 | G5: ravikiran.y@hyderabad.bits-pilani.ac.in | H5: Asst Professor | J5: Hyderabad | K5: =VLOOKUP(G5,Dataset!F:H,2,0) -> IISc Bangalore | L5: IISc Bangalore | M5: =VLOOKUP(G5,Dataset!F:H,3,0) -> TG 3 Design and Demonstration of a Highly Scalable Quantum Computer using Semiconducting Qubits | N5: TG 3 Design and Demonstration of a Highly Scalable Quantum Computer using Semiconducting Qubits
A6: 46082.977 | B6: Prasana | C6: Sahoo | D6: Academician/Researcher | E6: QMD/IIT Delhi Hub | F6: (+91) 7894525638 | G6: prasanasahoo@gmail.com | H6: Assistant Professor | J6: Kharagpur | K6: =VLOOKUP(G6,Dataset!F:H,2,0) -> #N/A | L6: IIT Delhi | M6: =VLOOKUP(G6,Dataset!F:H,3,0) -> #N/A | N6: TG2: Wafer-scale Emitter and Detector Arrays for Multi-wavelength RoomTemperature Photonic Quantum Technologie
A7: 46083.48 | B7: Prof. Rajesh | C7: Kumar | D7: Academician/Researcher | E7: QMD/ IITR | F7: (+91) 9643028327 | G7: rajesh.kumar@ph.iitr.ac.in | H7: Associate Professor | J7: Roorkee | K7: =VLOOKUP(G7,Dataset!F:H,2,0) -> #N/A | L7: IIT Delhi | M7: =VLOOKUP(G7,Dataset!F:H,3,0) -> #N/A | N7: TG3:WaveguideandIntegratedQuantumPhotonics
A8: 46084.82 | B8: Natarajan | C8: Venkatachalam | D8: Govt | F8: (+91) 9943195161 | G8: natarajan@setsindia.net | H8: Scientist E | I8: SETS | J8: Chennai | K8: =VLOOKUP(G8,Dataset!F:H,2,0) -> IISc Bangalore | L8: IISc Bangalore | M8: =VLOOKUP(G8,Dataset!F:H,3,0) -> QuILA | N8: QuILA
A9: 46085.454 | B9: Siddharth | C9: Tallur | D9: Academician/Researcher | E9: Qmet/IIT Bombay | F9: (+91) 8291020571 | G9: stallur@ee.iitb.ac.in | H9: Associate Professor | J9: Mumbai | K9: =VLOOKUP(G9,Dataset!F:H,2,0) -> IIT Bombay | L9: IIT Bombay | M9: =VLOOKUP(G9,Dataset!F:H,3,0) -> TG 3 Kasturi Saha | N9: TG 3 Kasturi Saha
A10: 46085.454 | B10: Phani | C10: Peddibhotla | D10: Academician/Researcher | E10: Qmet | F10: (+91) 8978535980 | G10: phani@iiserb.ac.in | H10: Asst. Prof. | J10: Bhopal | K10: =VLOOKUP(G10,Dataset!F:H,2,0) -> IIT Bombay | L10: IIT Bombay | M10: =VLOOKUP(G10,Dataset!F:H,3,0) -> TG 2 Saikat Ghosh | N10: TG 2 Saikat Ghosh
A11: 46085.455 | B11: Tanmoy | C11: Basu | D11: Academician/Researcher | E11: Quantum Sensing/TCG CREST | F11: (+91) 9040227037 | G11: tanmoy.basu@tcgcrest.org | H11: Assistant Professor | J11: Kolkata | K11: =VLOOKUP(G11,Dataset!F:H,2,0) -> IIT Bombay | L11: IIT Bombay | M11: =VLOOKUP(G11,Dataset!F:H,3,0) -> TG 3 Kasturi Saha | N11: TG 3 Kasturi Saha
A12: 46085.469 | B12: Santanu | C12: Talukder | D12: Academician/Researcher | E12: QMet | F12: (+91) 9632716218 | G12: santanu@iiserb.ac.in | H12: Associate Professor | J12: Bhopal | K12: =VLOOKUP(G12,Dataset!F:H,2,0) -> IIT Bombay | L12: IIT Bombay | M12: =VLOOKUP(G12,Dataset!F:H,3,0) -> TG 3 Kasturi Saha | N12: TG 3 Kasturi Saha
A13: 46085.471 | B13: Ambarish | C13: Ghosh | D13: Academician/Researcher | E13: IISc | F13: (95350) 22265 | G13: ambarish@iisc.ac.in | H13: Professor | J13: Bangalore | K13: =VLOOKUP(G13,Dataset!F:H,2,0) -> IIT Bombay | L13: IIT Bombay | M13: =VLOOKUP(G13,Dataset!F:H,3,0) -> TG 3 Kasturi Saha | N13: TG 3 Kasturi Saha
A14: 46085.491 | B14: Venkata Jayasurya | C14: Yallapragada | D14: Academician/Researcher | E14: IIT Kanpur | F14: (+91) 9441885075 | G14: jayasurya@iitk.ac.in | H14: Assistant Professor | J14: Kanpur | K14: =VLOOKUP(G14,Dataset!F:H,2,0) -> IIT Bombay | L14: IIT Bombay | M14: =VLOOKUP(G14,Dataset!F:H,3,0) -> TG 1 Anand Jha | N14: TG 1 Anand Jha
A15: 46085.502 | B15: Kasturi | C15: Saha | D15: Academician/Researcher | E15: Qmet Tech Foundation | F15: (+91) 8291020871 | G15: pic@qmettech.com | H15: Project Director | J15: Mumbai | K15: =VLOOKUP(G15,Dataset!F:H,2,0) -> IIT Bombay | L15: IIT Bombay | M15: =VLOOKUP(G15,Dataset!F:H,3,0) -> TG 3 Kasturi Saha | N15: TG 3 Kasturi Saha
A16: 46085.536 | B16: Bimalendu | C16: Deb | D16: Academician/Researcher | E16: Quantum sesing | F16: (91) 8420265902 | G16: msbd@iacs.res.in | H16: Professor | J16: Kolkata | K16: =VLOOKUP(G16,Dataset!F:H,2,0) -> IIT Bombay | L16: IIT Bombay | M16: =VLOOKUP(G16,Dataset!F:H,3,0) -> TG 2 Saikat Ghosh | N16: TG 2 Saikat Ghosh
A17: 46085.623 | B17: Sanjib | C17: Dey | D17: Academician/Researcher | E17: Quantum Sensing and Metrology/IIT Bombay | F17: (+91) 8617433466 | G17: sanjibd@goa.bits-pilani.ac.in | H17: Assistant Professor | J17: Goa | K17: =VLOOKUP(G17,Dataset!F:H,2,0) -> IIT Bombay | L17: IIT Bombay | M17: =VLOOKUP(G17,Dataset!F:H,3,0) -> TG 2 Saikat Ghosh | N17: TG 2 Saikat Ghosh
A18: 46085.828 | B18: Debapriya | C18: Basu Roy | D18: Academician/Researcher | E18: IIT Kanpur | F18: (+91) 9432149757 | G18: dbroy@cse.iitk.ac.in | H18: Assistant Professor | J18: Kanpur | K18: =VLOOKUP(G18,Dataset!F:H,2,0) -> IIT Madras | L18: IIT Madras | M18: =VLOOKUP(G18,Dataset!F:H,3,0) -> PIPETA: Post Quantum Cryptography | N18: PIPETA: Post Quantum Cryptography
A19: 46085.828 | B19: Ashish | C19: Arora | D19: Academician/Researcher | E19: IISER Pune | F19: (91) 9892294386 | G19: ashish.arora@iiserpune.ac.in | H19: Assistant Professor | J19: Pune | K19: =VLOOKUP(G19,Dataset!F:H,2,0) -> IIT Delhi | L19: IIT Delhi | M19: =VLOOKUP(G19,Dataset!F:H,3,0) -> TG2: Wafer-scale Emitter and Detector Arrays for Multi-wavelength RoomTemperature Photonic Quantum Technologies | N19: TG2: Wafer-scale Emitter and Detector Arrays for Multi-wavelength RoomTemperature Photonic Quantum Technologies
A20: 46085.876 | B20: Saikat | C20: Ghosh | D20: Academician/Researcher | E20: IIT-Kanpur | F20: (+91) 8545043528 | G20: gsaikat@iitk.ac.in | H20: Associate Professor | J20: Kanpur | K20: =VLOOKUP(G20,Dataset!F:H,2,0) -> IIT Bombay | L20: IIT Bombay | M20: =VLOOKUP(G20,Dataset!F:H,3,0) -> TG 2 Saikat Ghosh | N20: TG 2 Saikat Ghosh
... A33: 46091.359 | B33: Varun | C33: Raghunathan | D33: Academician/Researcher | E33: Indian Institute of Science | F33: (+91) 8939619026 | G33: varunr@iisc.ac.in | H33: Associate professor | J33: Bangalore | K33: =VLOOKUP(G33,Dataset!F:H,2,0) -> IIT Madras | L33: IIT Madras | M33: =VLOOKUP(G33,Dataset!F:H,3,0) -> QuILA | N33: QuILA
A34: 46091.385 | B34: Deepak | C34: Gaur | D34: Govt | F34: (+91) 9873209432 | G34: dgaur@cdot.in | H34: Scientist-F | I34: Centre for Development of Telematics | J34: New Delhi | K34: =VLOOKUP(G34,Dataset!F:H,2,0) -> IIT Madras | L34: IIT Madras | M34: =VLOOKUP(G34,Dataset!F:H,3,0) -> PIPETA: Post Quantum Cryptography | N34: PIPETA: Post Quantum Cryptography
A35: 46091.39 | B35: Sarani | C35: Bhattacharya | D35: Academician/Researcher | E35: MPI: IIT Kharagpur, TG: PIPETA | F35: (+91) 9477063861 | G35: bhattacharya.sarani.iitkgp@gmail.com | H35: Assistant Professor | J35: Kharagpur | K35: =VLOOKUP(G35,Dataset!F:H,2,0) -> #N/A | L35: IIT Madras | M35: =VLOOKUP(G35,Dataset!F:H,3,0) -> #N/A | N35: PIPETA: Post Quantum Cryptography
A36: 46091.412 | B36: Rajalakshmi | C36: Gurumurthy | D36: Academician/Researcher | E36: Rajalakshmi Gurumurthy | F36: (+91) 9963071783 | G36: raji@tifrh.res.in | H36: Scientific Officer (F) | J36: Hyderabad | K36: =VLOOKUP(G36,Dataset!F:H,2,0) -> IIT Bombay | L36: IIT Bombay | M36: =VLOOKUP(G36,Dataset!F:H,3,0) -> TG 2 Saikat Ghosh | N36: TG 2 Saikat Ghosh
A37: 46091.416 | B37: Saurabh | C37: Lodha | D37: Academician/Researcher | E37: IIT Bombay | F37: (+91) 9819927460 | G37: saurabh.lodha@gmail.com | H37: Professor | J37: Mumbai | K37: =VLOOKUP(G37,Dataset!F:H,2,0) -> #N/A | L37: IIT Delhi | M37: =VLOOKUP(G37,Dataset!F:H,3,0) -> #N/A | N37: TG2: Wafer-scale Emitter and Detector Arrays for Multi-wavelength RoomTemperature Photonic Quantum Technologies
A38: 46091.417 | B38: Prabha | C38: Mandayam | D38: Academician/Researcher | E38: FQCI/IIT Madras | F38: (+91) 9445992785 | G38: prabhamd@physics.iitm.ac.in | H38: Professor | J38: Chennai | K38: =VLOOKUP(G38,Dataset!F:H,2,0) -> IISc Bangalore | L38: IISc Bangalore | M38: =VLOOKUP(G38,Dataset!F:H,3,0) -> TG 5 Quantum computers with Superconducting Qubits | N38: TG 5 Quantum computers with Superconducting Qubits
A39: 46091.444 | B39: Shailendra K. | C39: Varshney | D39: Academician/Researcher | E39: IIT Kharagpur (QMD Hub) | F39: (+91) 9732926003 | G39: skvarshney@ece.iitkgp.ac.in | H39: Professor | J39: Kharagpur | K39: =VLOOKUP(G39,Dataset!F:H,2,0) -> IIT Delhi | L39: IIT Delhi | M39: =VLOOKUP(G39,Dataset!F:H,3,0) -> TG3:WaveguideandIntegratedQuantumPhotonics | N39: TG3:WaveguideandIntegratedQuantumPhotonics
A40: 46091.447 | B40: Akshay | C40: Naik | D40: Academician/Researcher | E40: IISc | F40: (+91) 9611396194 | G40: anaik@iisc.ac.in | H40: Professor | J40: Bangalore | K40: =VLOOKUP(G40,Dataset!F:H,2,0) -> IIT Bombay | L40: IIT Bombay | M40: =VLOOKUP(G40,Dataset!F:H,3,0) -> TG 2 Saikat Ghosh | N40: TG 2 Saikat Ghosh
A41: 46091.454 | B41: Rahul | C41: Singh | D41: Academician/Researcher | E41: Indian Institute of Technology, Bombay | F41: (91) 9004059586 | G41: rahuls_ee@iitb.ac.in | H41: Assistant Professor | J41: Mumbai | K41: =VLOOKUP(G41,Dataset!F:H,2,0) -> IISc Bangalore | L41: IISc Bangalore | M41: =VLOOKUP(G41,Dataset!F:H,3,0) -> TG 4 Development of a 50-qubit quantum information processor with electron spins in silicon | N41: TG 4 Development of a 50-qubit quantum information processor with electron spins in silicon
A42: 46091.493 | B42: Prosenjit | C42: Sen | D42: Academician/Researcher | E42: IISc | F42: (+91) 7406890351 | G42: prosenjits@iisc.ac.in | H42: Professor | J42: Bangalore | K42: =VLOOKUP(G42,Dataset!F:H,2,0) -> IIT Bombay | L42: IIT Bombay | M42: =VLOOKUP(G42,Dataset!F:H,3,0) -> TG 2 Saikat Ghosh | N42: TG 2 Saikat Ghosh
A43: 46091.587 | B43: SAMARESH | C43: DAS | D43: Academician/Researcher | E43: IIT DELHI | F43: (91) 9899130814 | G43: samareshdas@care.iitd.ac.in | H43: Professor | J43: Delhi | K43: =VLOOKUP(G43,Dataset!F:H,2,0) -> #N/A | L43: IISc Banglore | M43: =VLOOKUP(G43,Dataset!F:H,3,0) -> #N/A | N43: TG 4 Development of a 50-qubit quantum information processor with electron spins in silicon
A44: 46091.66 | B44: Madhu | C44: Thalakulam | D44: Academician/Researcher | E44: FQCI/IISER Thiruvananthapuram | F44: (91) 9497785983 | G44: madhu@iisertvm.ac.in | H44: Associate Professor | J44: Thiruvananthapuram | K44: =VLOOKUP(G44,Dataset!F:H,2,0) -> IISc Bangalore | L44: =K44 -> IISc Bangalore | M44: =VLOOKUP(G44,Dataset!F:H,3,0) -> TG 4 Development of a 50-qubit quantum information processor with electron spins in silicon | N44: =M44 -> TG 4 Development of a 50-qubit quantum information processor with electron spins in silicon
A45: 46091.662 | B45: Senthil Kumar | C45: M | D45: Govt | F45: (+91) 9427048883 | G45: senthiliist@gmail.com | H45: LPI NQM | I45: SAC, ISRO | J45: Ahmedabad | K45: =VLOOKUP(G45,Dataset!F:H,2,0) -> #N/A | L45: IIT Madras | M45: =VLOOKUP(G45,Dataset!F:H,3,0) -> #N/A | N45: SBQKD - ISRO
A46: 46091.702 | B46: Dr. Avinash | C46: Lahgere | D46: Academician/Researcher | E46: IIT Kanpur | F46: (91) 9711611954 | G46: alahgere@iitk.ac.in | H46: Assistant Professor | J46: Kanpur | K46: =VLOOKUP(G46,Dataset!F:H,2,0) -> IISc Bangalore | L46: =K46 -> IISc Bangalore | M46: =VLOOKUP(G46,Dataset!F:H,3,0) -> TG 3 Design and Demonstration of a Highly Scalable Quantum Computer using Semiconducting Qubits | N46: =M46 -> TG 3 Design and Demonstration of a Highly Scalable Quantum Computer using Semiconducting Qubits
A47: 46091.769 | B47: Anil | C47: Shaji | D47: Academician/Researcher | E47: Quantum Computing Hub - TG4 - IISER TVM (Member Institute) | F47: (+91) 9446460011 | G47: shaji@iisertvm.ac.in | H47: Professor | J47: Thiruvananthapuram | K47: =VLOOKUP(G47,Dataset!F:H,2,0) -> #N/A | L47: IISc Banglore | M47: =VLOOKUP(G47,Dataset!F:H,3,0) -> #N/A | N47: TG 4 Development of a 50-qubit quantum information processor with electron spins in silicon
